Workbook

Sheet Summary
A1: Little Kettle Shop | Sales Summary
A4: Key numbers | E4: Revenue by country
A5: Revenue | B5: =SUM('Clean Data'!$I$2:$I$301) -> 14306.2 | E5: Country | F5: Orders | G5: Revenue | H5: Share
A6: Orders | B6: =COUNTA('Clean Data'!$A$2:$A$301) -> 300 | E6: Netherlands | F6: =COUNTIFS('Clean Data'!$D$2:$D$301,E6) -> 173 | G6: =SUMIFS('Clean Data'!$I$2:$I$301,'Clean Data'!$D$2:$D$301,E6) -> 7775.25 | H6: =IFERROR(G6/$B$5,0) -> 0.54348814
A7: Items sold | B7: =SUM('Clean Data'!$G$2:$G$301) -> 462 | E7: Germany | F7: =COUNTIFS('Clean Data'!$D$2:$D$301,E7) -> 60 | G7: =SUMIFS('Clean Data'!$I$2:$I$301,'Clean Data'!$D$2:$D$301,E7) -> 3060.95 | H7: =IFERROR(G7/$B$5,0) -> 0.21395968
A8: Average order value | B8: =IFERROR(B5/COUNT('Clean Data'!$I$2:$I$301),0) -> 48.660544 | E8: Belgium | F8: =COUNTIFS('Clean Data'!$D$2:$D$301,E8) -> 43 | G8: =SUMIFS('Clean Data'!$I$2:$I$301,'Clean Data'!$D$2:$D$301,E8) -> 2187.35 | H8: =IFERROR(G8/$B$5,0) -> 0.15289525
A9: Rows flagged for review | B9: =SUMPRODUCT(--('Clean Data'!$L$2:$L$301<>"")) -> 10 | E9: France | F9: =COUNTIFS('Clean Data'!$D$2:$D$301,E9) -> 20 | G9: =SUMIFS('Clean Data'!$I$2:$I$301,'Clean Data'!$D$2:$D$301,E9) -> 1047.95 | H9: =IFERROR(G9/$B$5,0) -> 0.073251457
E10: Missing country | F10: =COUNTIFS('Clean Data'!$D$2:$D$301,"") -> 4
A11: Revenue by month
A12: Month | B12: Orders | C12: Revenue | E12: Revenue by product
A13: 46204 | B13: =COUNTIFS('Clean Data'!$K$2:$K$301,A13) -> 85 | C13: =SUMIFS('Clean Data'!$I$2:$I$301,'Clean Data'!$K$2:$K$301,A13) -> 4599.65 | E13: Product | F13: Qty sold | G13: Revenue
A14: 46235 | B14: =COUNTIFS('Clean Data'!$K$2:$K$301,A14) -> 97 | C14: =SUMIFS('Clean Data'!$I$2:$I$301,'Clean Data'!$K$2:$K$301,A14) -> 4481.55 | E14: =Products!A2 -> French Press 1L | F14: =SUMIFS('Clean Data'!$G$2:$G$301,'Clean Data'!$E$2:$E$301,E14) -> 102 | G14: =SUMIFS('Clean Data'!$I$2:$I$301,'Clean Data'!$E$2:$E$301,E14) -> 2995
A15: 46266 | B15: =COUNTIFS('Clean Data'!$K$2:$K$301,A15) -> 66 | C15: =SUMIFS('Clean Data'!$I$2:$I$301,'Clean Data'!$K$2:$K$301,A15) -> 2728.65 | E15: =Products!A3 -> Ceramic Mug Set (4) | F15: =SUMIFS('Clean Data'!$G$2:$G$301,'Clean Data'!$E$2:$E$301,E15) -> 77 | G15: =SUMIFS('Clean Data'!$I$2:$I$301,'Clean Data'!$E$2:$E$301,E15) -> 1896.2
A16: 46296 | B16: =COUNTIFS('Clean Data'!$K$2:$K$301,A16) -> 52 | C16: =SUMIFS('Clean Data'!$I$2:$I$301,'Clean Data'!$K$2:$K$301,A16) -> 2496.35 | E16: =Products!A4 -> Pour-Over Kettle | F16: =SUMIFS('Clean Data'!$G$2:$G$301,'Clean Data'!$E$2:$E$301,E16) -> 47 | G16: =SUMIFS('Clean Data'!$I$2:$I$301,'Clean Data'!$E$2:$E$301,E16) -> 2303
E17: =Products!A5 -> Coffee Grinder | F17: =SUMIFS('Clean Data'!$G$2:$G$301,'Clean Data'!$E$2:$E$301,E17) -> 46 | G17: =SUMIFS('Clean Data'!$I$2:$I$301,'Clean Data'!$E$2:$E$301,E17) -> 1837.7
E18: =Products!A6 -> Glass Teapot | F18: =SUMIFS('Clean Data'!$G$2:$G$301,'Clean Data'!$E$2:$E$301,E18) -> 43 | G18: =SUMIFS('Clean Data'!$I$2:$I$301,'Clean Data'!$E$2:$E$301,E18) -> 1182.5
E19: =Products!A7 -> Cast Iron Pan 26cm | F19: =SUMIFS('Clean Data'!$G$2:$G$301,'Clean Data'!$E$2:$E$301,E19) -> 29 | G19: =SUMIFS('Clean Data'!$I$2:$I$301,'Clean Data'!$E$2:$E$301,E19) -> 1258.6
E20: =Products!A8 -> Linen Tea Towels (2) | F20: =SUMIFS('Clean Data'!$G$2:$G$301,'Clean Data'!$E$2:$E$301,E20) -> 56 | G20: =SUMIFS('Clean Data'!$I$2:$I$301,'Clean Data'!$E$2:$E$301,E20) -> 725.2
E21: =Products!A9 -> Oak Cutting Board | F21: =SUMIFS('Clean Data'!$G$2:$G$301,'Clean Data'!$E$2:$E$301,E21) -> 62 | G21: =SUMIFS('Clean Data'!$I$2:$I$301,'Clean Data'!$E$2:$E$301,E21) -> 2108

Sheet Clean Data
A1: Order ID | B1: Order Date | C1: Customer | D1: Country | E1: Product | F1: Category | G1: Qty | H1: Unit Price | I1: Total | J1: Payment | K1: Month | L1: Check
A2: LK-2012 | B2: 46207 | C2: Max Dubois | D2: Netherlands | E2: Linen Tea Towels (2) | F2: =IFERROR(INDEX(Products!$B$2:$B$9,MATCH(E2,Products!$A$2:$A$9,0)),"Unknown product") -> Textiles | G2: 1 | H2: 12.95 | I2: =IF(OR(G2="",L2="Price differs from list"),"",G2*H2) -> 12.95 | J2: iDEAL | K2: =DATE(YEAR(B2),MONTH(B2),1) -> 46204 | L2: =IF(G2="","Missing qty",IF(D2="","Missing country",IF(ABS(H2-INDEX(Products!$C$2:$C$9,MATCH(E2,Products!$A$2:$A$9,0)))>0.005,"Price differs from list","")))
A3: LK-2020 | B3: 46210 | C3: Sem Meijer | D3: Germany | E3: Linen Tea Towels (2) | F3: =IFERROR(INDEX(Products!$B$2:$B$9,MATCH(E3,Products!$A$2:$A$9,0)),"Unknown product") -> Textiles | G3: 1 | H3: 12.95 | I3: =IF(OR(G3="",L3="Price differs from list"),"",G3*H3) -> 12.95 | J3: PayPal | K3: =DATE(YEAR(B3),MONTH(B3),1) -> 46204 | L3: =IF(G3="","Missing qty",IF(D3="","Missing country",IF(ABS(H3-INDEX(Products!$C$2:$C$9,MATCH(E3,Products!$A$2:$A$9,0)))>0.005,"Price differs from list","")))
A4: LK-2027 | B4: 46211 | C4: Emma Bakker | D4: Belgium | E4: Linen Tea Towels (2) | F4: =IFERROR(INDEX(Products!$B$2:$B$9,MATCH(E4,Products!$A$2:$A$9,0)),"Unknown product") -> Textiles | G4: 1 | H4: 12.95 | I4: =IF(OR(G4="",L4="Price differs from list"),"",G4*H4) -> 12.95 | J4: Card | K4: =DATE(YEAR(B4),MONTH(B4),1) -> 46204 | L4: =IF(G4="","Missing qty",IF(D4="","Missing country",IF(ABS(H4-INDEX(Products!$C$2:$C$9,MATCH(E4,Products!$A$2:$A$9,0)))>0.005,"Price differs from list","")))
A5: LK-2054 | B5: 46220 | C5: Lea Peeters | D5: Belgium | E5: Linen Tea Towels (2) | F5: =IFERROR(INDEX(Products!$B$2:$B$9,MATCH(E5,Products!$A$2:$A$9,0)),"Unknown product") -> Textiles | G5: 1 | H5: 12.95 | I5: =IF(OR(G5="",L5="Price differs from list"),"",G5*H5) -> 12.95 | J5: Card | K5: =DATE(YEAR(B5),MONTH(B5),1) -> 46204 | L5: =IF(G5="","Missing qty",IF(D5="","Missing country",IF(ABS(H5-INDEX(Products!$C$2:$C$9,MATCH(E5,Products!$A$2:$A$9,0)))>0.005,"Price differs from list","")))
A6: LK-2071 | B6: 46229 | C6: Sophie Bos | D6: Netherlands | E6: Linen Tea Towels (2) | F6: =IFERROR(INDEX(Products!$B$2:$B$9,MATCH(E6,Products!$A$2:$A$9,0)),"Unknown product") -> Textiles | G6: 1 | H6: 12.95 | I6: =IF(OR(G6="",L6="Price differs from list"),"",G6*H6) -> 12.95 | J6: PayPal | K6: =DATE(YEAR(B6),MONTH(B6),1) -> 46204 | L6: =IF(G6="","Missing qty",IF(D6="","Missing country",IF(ABS(H6-INDEX(Products!$C$2:$C$9,MATCH(E6,Products!$A$2:$A$9,0)))>0.005,"Price differs from list","")))
A7: LK-2088 | B7: 46235 | C7: Noah Dubois | D7: Netherlands | E7: Linen Tea Towels (2) | F7: =IFERROR(INDEX(Products!$B$2:$B$9,MATCH(E7,Products!$A$2:$A$9,0)),"Unknown product") -> Textiles | G7: 1 | H7: 12.95 | I7: =IF(OR(G7="",L7="Price differs from list"),"",G7*H7) -> 12.95 | J7: iDEAL | K7: =DATE(YEAR(B7),MONTH(B7),1) -> 46235 | L7: =IF(G7="","Missing qty",IF(D7="","Missing country",IF(ABS(H7-INDEX(Products!$C$2:$C$9,MATCH(E7,Products!$A$2:$A$9,0)))>0.005,"Price differs from list","")))
A8: LK-2091 | B8: 46236 | C8: Emma Jansen | D8: France | E8: Linen Tea Towels (2) | F8: =IFERROR(INDEX(Products!$B$2:$B$9,MATCH(E8,Products!$A$2:$A$9,0)),"Unknown product") -> Textiles | G8: 1 | H8: 12.95 | I8: =IF(OR(G8="",L8="Price differs from list"),"",G8*H8) -> 12.95 | J8: Card | K8: =DATE(YEAR(B8),MONTH(B8),1) -> 46235 | L8: =IF(G8="","Missing qty",IF(D8="","Missing country",IF(ABS(H8-INDEX(Products!$C$2:$C$9,MATCH(E8,Products!$A$2:$A$9,0)))>0.005,"Price differs from list","")))
A9: LK-2109 | B9: 46243 | C9: Finn Visser | D9: Netherlands | E9: Linen Tea Towels (2) | F9: =IFERROR(INDEX(Products!$B$2:$B$9,MATCH(E9,Products!$A$2:$A$9,0)),"Unknown product") -> Textiles | G9: 1 | H9: 12.95 | I9: =IF(OR(G9="",L9="Price differs from list"),"",G9*H9) -> 12.95 | J9: Card | K9: =DATE(YEAR(B9),MONTH(B9),1) -> 46235 | L9: =IF(G9="","Missing qty",IF(D9="","Missing country",IF(ABS(H9-INDEX(Products!$C$2:$C$9,MATCH(E9,Products!$A$2:$A$9,0)))>0.005,"Price differs from list","")))
A10: LK-2133 | B10: 46251 | C10: Anna de Vries | D10: Netherlands | E10: Linen Tea Towels (2) | F10: =IFERROR(INDEX(Products!$B$2:$B$9,MATCH(E10,Products!$A$2:$A$9,0)),"Unknown product") -> Textiles | G10: 1 | H10: 12.95 | I10: =IF(OR(G10="",L10="Price differs from list"),"",G10*H10) -> 12.95 | J10: Card | K10: =DATE(YEAR(B10),MONTH(B10),1) -> 46235 | L10: =IF(G10="","Missing qty",IF(D10="","Missing country",IF(ABS(H10-INDEX(Products!$C$2:$C$9,MATCH(E10,Products!$A$2:$A$9,0)))>0.005,"Price differs from list","")))
A11: LK-2162 | B11: 46259 | C11: Marie Hendriks | D11: Netherlands | E11: Linen Tea Towels (2) | F11: =IFERROR(INDEX(Products!$B$2:$B$9,MATCH(E11,Products!$A$2:$A$9,0)),"Unknown product") -> Textiles | G11: 1 | H11: 12.95 | I11: =IF(OR(G11="",L11="Price differs from list"),"",G11*H11) -> 12.95 | J11: Card | K11: =DATE(YEAR(B11),MONTH(B11),1) -> 46235 | L11: =IF(G11="","Missing qty",IF(D11="","Missing country",IF(ABS(H11-INDEX(Products!$C$2:$C$9,MATCH(E11,Products!$A$2:$A$9,0)))>0.005,"Price differs from list","")))
A12: LK-2166 | B12: 46262 | C12: Lotte Bakker | D12: Netherlands | E12: Linen Tea Towels (2) | F12: =IFERROR(INDEX(Products!$B$2:$B$9,MATCH(E12,Products!$A$2:$A$9,0)),"Unknown product") -> Textiles | G12: 1 | H12: 12.95 | I12: =IF(OR(G12="",L12="Price differs from list"),"",G12*H12) -> 12.95 | J12: Card | K12: =DATE(YEAR(B12),MONTH(B12),1) -> 46235 | L12: =IF(G12="","Missing qty",IF(D12="","Missing country",IF(ABS(H12-INDEX(Products!$C$2:$C$9,MATCH(E12,Products!$A$2:$A$9,0)))>0.005,"Price differs from list","")))
A13: LK-2175 | B13: 46265 | C13: Nora Müller | D13: Netherlands | E13: Linen Tea Towels (2) | F13: =IFERROR(INDEX(Products!$B$2:$B$9,MATCH(E13,Products!$A$2:$A$9,0)),"Unknown product") -> Textiles | G13: 1 | H13: 12.95 | I13: =IF(OR(G13="",L13="Price differs from list"),"",G13*H13) -> 12.95 | J13: iDEAL | K13: =DATE(YEAR(B13),MONTH(B13),1) -> 46235 | L13: =IF(G13="","Missing qty",IF(D13="","Missing country",IF(ABS(H13-INDEX(Products!$C$2:$C$9,MATCH(E13,Products!$A$2:$A$9,0)))>0.005,"Price differs from list","")))
... A88: LK-2163 | B88: 46260 | C88: Sara Dubois | D88: Germany | E88: Ceramic Mug Set (4) | F88: =IFERROR(INDEX(Products!$B$2:$B$9,MATCH(E88,Products!$A$2:$A$9,0)),"Unknown product") -> Tableware | G88: 4 | H88: 24.95 | I88: =IF(OR(G88="",L88="Price differs from list"),"",G88*H88) -> 99.8 | J88: Card | K88: =DATE(YEAR(B88),MONTH(B88),1) -> 46235 | L88: =IF(G88="","Missing qty",IF(D88="","Missing country",IF(ABS(H88-INDEX(Products!$C$2:$C$9,MATCH(E88,Products!$A$2:$A$9,0)))>0.005,"Price differs from list","")))
A89: LK-2086 | B89: 46235 | C89: Emma Bakker | D89: Netherlands | E89: Ceramic Mug Set (4) | F89: =IFERROR(INDEX(Products!$B$2:$B$9,MATCH(E89,Products!$A$2:$A$9,0)),"Unknown product") -> Tableware | H89: 24.95 | I89: =IF(OR(G89="",L89="Price differs from list"),"",G89*H89) | J89: PayPal | K89: =DATE(YEAR(B89),MONTH(B89),1) -> 46235 | L89: =IF(G89="","Missing qty",IF(D89="","Missing country",IF(ABS(H89-INDEX(Products!$C$2:$C$9,MATCH(E89,Products!$A$2:$A$9,0)))>0.005,"Price differs from list",""))) -> Missing qty
A90: LK-2030 | B90: 46212 | C90: Sem Visser | D90: Netherlands | E90: Glass Teapot | F90: =IFERROR(INDEX(Products!$B$2:$B$9,MATCH(E90,Products!$A$2:$A$9,0)),"Unknown product") -> Tea | G90: 1 | H90: 27.5 | I90: =IF(OR(G90="",L90="Price differs from list"),"",G90*H90) -> 27.5 | J90: Card | K90: =DATE(YEAR(B90),MONTH(B90),1) -> 46204 | L90: =IF(G90="","Missing qty",IF(D90="","Missing country",IF(ABS(H90-INDEX(Products!$C$2:$C$9,MATCH(E90,Products!$A$2:$A$9,0)))>0.005,"Price differs from list","")))
A91: LK-2043 | B91: 46215 | C91: Claire Hendriks | D91: Netherlands | E91: Glass Teapot | F91: =IFERROR(INDEX(Products!$B$2:$B$9,MATCH(E91,Products!$A$2:$A$9,0)),"Unknown product") -> Tea | G91: 1 | H91: 27.5 | I91: =IF(OR(G91="",L91="Price differs from list"),"",G91*H91) -> 27.5 | J91: iDEAL | K91: =DATE(YEAR(B91),MONTH(B91),1) -> 46204 | L91: =IF(G91="","Missing qty",IF(D91="","Missing country",IF(ABS(H91-INDEX(Products!$C$2:$C$9,MATCH(E91,Products!$A$2:$A$9,0)))>0.005,"Price differs from list","")))
A92: LK-2053 | B92: 46220 | C92: Noah Bakker | D92: Netherlands | E92: Glass Teapot | F92: =IFERROR(INDEX(Products!$B$2:$B$9,MATCH(E92,Products!$A$2:$A$9,0)),"Unknown product") -> Tea | G92: 1 | H92: 27.5 | I92: =IF(OR(G92="",L92="Price differs from list"),"",G92*H92) -> 27.5 | J92: iDEAL | K92: =DATE(YEAR(B92),MONTH(B92),1) -> 46204 | L92: =IF(G92="","Missing qty",IF(D92="","Missing country",IF(ABS(H92-INDEX(Products!$C$2:$C$9,MATCH(E92,Products!$A$2:$A$9,0)))>0.005,"Price differs from list","")))
A93: LK-2090 | B93: 46236 | C93: Eva Müller | D93: Belgium | E93: Glass Teapot | F93: =IFERROR(INDEX(Products!$B$2:$B$9,MATCH(E93,Products!$A$2:$A$9,0)),"Unknown product") -> Tea | G93: 1 | H93: 27.5 | I93: =IF(OR(G93="",L93="Price differs from list"),"",G93*H93) -> 27.5 | J93: Card | K93: =DATE(YEAR(B93),MONTH(B93),1) -> 46235 | L93: =IF(G93="","Missing qty",IF(D93="","Missing country",IF(ABS(H93-INDEX(Products!$C$2:$C$9,MATCH(E93,Products!$A$2:$A$9,0)))>0.005,"Price differs from list","")))
A94: LK-2108 | B94: 46243 | C94: Claire Meijer | D94: Netherlands | E94: Glass Teapot | F94: =IFERROR(INDEX(Products!$B$2:$B$9,MATCH(E94,Products!$A$2:$A$9,0)),"Unknown product") -> Tea | G94: 1 | H94: 27.5 | I94: =IF(OR(G94="",L94="Price differs from list"),"",G94*H94) -> 27.5 | J94: PayPal | K94: =DATE(YEAR(B94),MONTH(B94),1) -> 46235 | L94: =IF(G94="","Missing qty",IF(D94="","Missing country",IF(ABS(H94-INDEX(Products!$C$2:$C$9,MATCH(E94,Products!$A$2:$A$9,0)))>0.005,"Price differs from list","")))
A95: LK-2121 | B95: 46248 | C95: Levi Bos | D95: Germany | E95: Glass Teapot | F95: =IFERROR(INDEX(Products!$B$2:$B$9,MATCH(E95,Products!$A$2:$A$9,0)),"Unknown product") -> Tea | G95: 1 | H95: 27.5 | I95: =IF(OR(G95="",L95="Price differs from list"),"",G95*H95) -> 27.5 | J95: Card | K95: =DATE(YEAR(B95),MONTH(B95),1) -> 46235 | L95: =IF(G95="","Missing qty",IF(D95="","Missing country",IF(ABS(H95-INDEX(Products!$C$2:$C$9,MATCH(E95,Products!$A$2:$A$9,0)))>0.005,"Price differs from list","")))
A96: LK-2122 | B96: 46248 | C96: Jonas Schmidt | D96: Belgium | E96: Glass Teapot | F96: =IFERROR(INDEX(Products!$B$2:$B$9,MATCH(E96,Products!$A$2:$A$9,0)),"Unknown product") -> Tea | G96: 1 | H96: 27.5 | I96: =IF(OR(G96="",L96="Price differs from list"),"",G96*H96) -> 27.5 | J96: Card | K96: =DATE(YEAR(B96),MONTH(B96),1) -> 46235 | L96: =IF(G96="","Missing qty",IF(D96="","Missing country",IF(ABS(H96-INDEX(Products!$C$2:$C$9,MATCH(E96,Products!$A$2:$A$9,0)))>0.005,"Price differs from list","")))
A97: LK-2139 | B97: 46253 | C97: Lea Martin | D97: Netherlands | E97: Glass Teapot | F97: =IFERROR(INDEX(Products!$B$2:$B$9,MATCH(E97,Products!$A$2:$A$9,0)),"Unknown product") -> Tea | G97: 1 | H97: 27.5 | I97: =IF(OR(G97="",L97="Price differs from list"),"",G97*H97) -> 27.5 | J97: Card | K97: =DATE(YEAR(B97),MONTH(B97),1) -> 46235 | L97: =IF(G97="","Missing qty",IF(D97="","Missing country",IF(ABS(H97-INDEX(Products!$C$2:$C$9,MATCH(E97,Products!$A$2:$A$9,0)))>0.005,"Price differs from list","")))
A98: LK-2190 | B98: 46269 | C98: Anna Wagner | D98: Netherlands | E98: Glass Teapot | F98: =IFERROR(INDEX(Products!$B$2:$B$9,MATCH(E98,Products!$A$2:$A$9,0)),"Unknown product") -> Tea | G98: 1 | H98: 27.5 | I98: =IF(OR(G98="",L98="Price differs from list"),"",G98*H98) -> 27.5 | J98: iDEAL | K98: =DATE(YEAR(B98),MONTH(B98),1) -> 46266 | L98: =IF(G98="","Missing qty",IF(D98="","Missing country",IF(ABS(H98-INDEX(Products!$C$2:$C$9,MATCH(E98,Products!$A$2:$A$9,0)))>0.005,"Price differs from list","")))
A99: LK-2205 | B99: 46277 | C99: Julia Hendriks | D99: Netherlands | E99: Glass Teapot | F99: =IFERROR(INDEX(Products!$B$2:$B$9,MATCH(E99,Products!$A$2:$A$9,0)),"Unknown product") -> Tea | G99: 1 | H99: 27.5 | I99: =IF(OR(G99="",L99="Price differs from list"),"",G99*H99) -> 27.5 | J99: PayPal | K99: =DATE(YEAR(B99),MONTH(B99),1) -> 46266 | L99: =IF(G99="","Missing qty",IF(D99="","Missing country",IF(ABS(H99-INDEX(Products!$C$2:$C$9,MATCH(E99,Products!$A$2:$A$9,0)))>0.005,"Price differs from list","")))
A100: LK-2207 | B100: 46277 | C100: Finn Meijer | D100: Netherlands | E100: Glass Teapot | F100: =IFERROR(INDEX(Products!$B$2:$B$9,MATCH(E100,Products!$A$2:$A$9,0)),"Unknown product") -> Tea | G100: 1 | H100: 27.5 | I100: =IF(OR(G100="",L100="Price differs from list"),"",G100*H100) -> 27.5 | J100: Card | K100: =DATE(YEAR(B100),MONTH(B100),1) -> 46266 | L100: =IF(G100="","Missing qty",IF(D100="","Missing country",IF(ABS(H100-INDEX(Products!$C$2:$C$9,MATCH(E100,Products!$A$2:$A$9,0)))>0.005,"Price differs from list","")))
A101: LK-2210 | B101: 46277 | C101: Liam Martin | D101: Netherlands | E101: Glass Teapot | F101: =IFERROR(INDEX(Products!$B$2:$B$9,MATCH(E101,Products!$A$2:$A$9,0)),"Unknown product") -> Tea | G101: 1 | H101: 27.5 | I101: =IF(OR(G101="",L101="Price differs from list"),"",G101*H101) -> 27.5 | J101: Card | K101: =DATE(YEAR(B101),MONTH(B101),1) -> 46266 | L101: =IF(G101="","Missing qty",IF(D101="","Missing country",IF(ABS(H101-INDEX(Products!$C$2:$C$9,MATCH(E101,Products!$A$2:$A$9,0)))>0.005,"Price differs from list","")))
... A137: LK-2218 | B137: 46280 | C137: Julia Maes | D137: Netherlands | E137: French Press 1L | F137: =IFERROR(INDEX(Products!$B$2:$B$9,MATCH(E137,Products!$A$2:$A$9,0)),"Unknown product") -> Coffee | G137: 1 | H137: 29.95 | I137: =IF(OR(G137="",L137="Price differs from list"),"",G137*H137) -> 29.95 | J137: iDEAL | K137: =DATE(YEAR(B137),MONTH(B137),1) -> 46266 | L137: =IF(G137="","Missing qty",IF(D137="","Missing country",IF(ABS(H137-INDEX(Products!$C$2:$C$9,MATCH(E137,Products!$A$2:$A$9,0)))>0.005,"Price differs from list","")))
A138: LK-2237 | B138: 46290 | C138: Hugo Visser | E138: French Press 1L | F138: =IFERROR(INDEX(Products!$B$2:$B$9,MATCH(E138,Products!$A$2:$A$9,0)),"Unknown product") -> Coffee | G138: 1 | H138: 29.95 | I138: =IF(OR(G138="",L138="Price differs from list"),"",G138*H138) -> 29.95 | J138: Card | K138: =DATE(YEAR(B138),MONTH(B138),1) -> 46266 | L138: =IF(G138="","Missing qty",IF(D138="","Missing country",IF(ABS(H138-INDEX(Products!$C$2:$C$9,MATCH(E138,Products!$A$2:$A$9,0)))>0.005,"Price differs from list",""))) -> Missing country
A139: LK-2241 | B139: 46292 | C139: Liam Hendriks | D139: Netherlands | E139: French Press 1L | F139: =IFERROR(INDEX(Products!$B$2:$B$9,MATCH(E139,Products!$A$2:$A$9,0)),"Unknown product") -> Coffee | G139: 1 | H139: 29.95 | I139: =IF(OR(G139="",L139="Price differs from list"),"",G139*H139) -> 29.95 | J139: PayPal | K139: =DATE(YEAR(B139),MONTH(B139),1) -> 46266 | L139: =IF(G139="","Missing qty",IF(D139="","Missing country",IF(ABS(H139-INDEX(Products!$C$2:$C$9,MATCH(E139,Products!$A$2:$A$9,0)))>0.005,"Price differs from list","")))
A140: LK-2249 | B140: 46296 | C140: Lucas Bos | D140: Netherlands | E140: French Press 1L | F140: =IFERROR(INDEX(Products!$B$2:$B$9,MATCH(E140,Products!$A$2:$A$9,0)),"Unknown product") -> Coffee | G140: 1 | H140: 29.95 | I140: =IF(OR(G140="",L140="Price differs from list"),"",G140*H140) -> 29.95 | J140: PayPal | K140: =DATE(YEAR(B140),MONTH(B140),1) -> 46296 | L140: =IF(G140="","Missing qty",IF(D140="","Missing country",IF(ABS(H140-INDEX(Products!$C$2:$C$9,MATCH(E140,Products!$A$2:$A$9,0)))>0.005,"Price differs from list","")))
A141: LK-2250 | B141: 46297 | C141: Sem Maes | D141: Netherlands | E141: French Press 1L | F141: =IFERROR(INDEX(Products!$B$2:$B$9,MATCH(E141,Products!$A$2:$A$9,0)),"Unknown product") -> Coffee | G141: 1 | H141: 29.95 | I141: =IF(OR(G141="",L141="Price differs from list"),"",G141*H141) -> 29.95 | J141: iDEAL | K141: =DATE(YEAR(B141),MONTH(B141),1) -> 46296 | L141: =IF(G141="","Missing qty",IF(D141="","Missing country",IF(ABS(H141-INDEX(Products!$C$2:$C$9,MATCH(E141,Products!$A$2:$A$9,0)))>0.005,"Price differs from list","")))
A142: LK-2255 | B142: 46299 | C142: Emma Bakker | E142: French Press 1L | F142: =IFERROR(INDEX(Products!$B$2:$B$9,MATCH(E142,Products!$A$2:$A$9,0)),"Unknown product") -> Coffee | G142: 1 | H142: 29.95 | I142: =IF(OR(G142="",L142="Price differs from list"),"",G142*H142) -> 29.95 | J142: iDEAL | K142: =DATE(YEAR(B142),MONTH(B142),1) -> 46296 | L142: =IF(G142="","Missing qty",IF(D142="","Missing country",IF(ABS(H142-INDEX(Products!$C$2:$C$9,MATCH(E142,Products!$A$2:$A$9,0)))>0.005,"Price differs from list",""))) -> Missing country
A143: LK-2298 | B143: 46315 | C143: Eva Meijer | D143: Netherlands | E143: French Press 1L | F143: =IFERROR(INDEX(Products!$B$2:$B$9,MATCH(E143,Products!$A$2:$A$9,0)),"Unknown product") -> Coffee | G143: 1 | H143: 29.95 | I143: =IF(OR(G143="",L143="Price differs from list"),"",G143*H143) -> 29.95 | J143: PayPal | K143: =DATE(YEAR(B143),MONTH(B143),1) -> 46296 | L143: =IF(G143="","Missing qty",IF(D143="","Missing country",IF(ABS(H143-INDEX(Products!$C$2:$C$9,MATCH(E143,Products!$A$2:$A$9,0)))>0.005,"Price differs from list","")))
A144: LK-2300 | B144: 46315 | C144: Lena Hendriks | D144: Netherlands | E144: French Press 1L | F144: =IFERROR(INDEX(Products!$B$2:$B$9,MATCH(E144,Products!$A$2:$A$9,0)),"Unknown product") -> Coffee | G144: 1 | H144: 29.95 | I144: =IF(OR(G144="",L144="Price differs from list"),"",G144*H144) -> 29.95 | J144: Card | K144: =DATE(YEAR(B144),MONTH(B144),1) -> 46296 | L144: =IF(G144="","Missing qty",IF(D144="","Missing country",IF(ABS(H144-INDEX(Products!$C$2:$C$9,MATCH(E144,Products!$A$2:$A$9,0)))>0.005,"Price differs from list","")))
A145: LK-2013 | B145: 46207 | C145: Marie Jansen | D145: Germany | E145: French Press 1L | F145: =IFERROR(INDEX(Products!$B$2:$B$9,MATCH(E145,Products!$A$2:$A$9,0)),"Unknown product") -> Coffee | G145: 2 | H145: 29.95 | I145: =IF(OR(G145="",L145="Price differs from list"),"",G145*H145) -> 59.9 | J145: PayPal | K145: =DATE(YEAR(B145),MONTH(B145),1) -> 46204 | L145: =IF(G145="","Missing qty",IF(D145="","Missing country",IF(ABS(H145-INDEX(Products!$C$2:$C$9,MATCH(E145,Products!$A$2:$A$9,0)))>0.005,"Price differs from list","")))
A146: LK-2016 | B146: 46208 | C146: Paul Hendriks | D146: Belgium | E146: French Press 1L | F146: =IFERROR(INDEX(Products!$B$2:$B$9,MATCH(E146,Products!$A$2:$A$9,0)),"Unknown product") -> Coffee | G146: 2 | H146: 29.95 | I146: =IF(OR(G146="",L146="Price differs from list"),"",G146*H146) -> 59.9 | J146: PayPal | K146: =DATE(YEAR(B146),MONTH(B146),1) -> 46204 | L146: =IF(G146="","Missing qty",IF(D146="","Missing country",IF(ABS(H146-INDEX(Products!$C$2:$C$9,MATCH(E146,Products!$A$2:$A$9,0)))>0.005,"Price differs from list","")))
A147: LK-2028 | B147: 46211 | C147: Finn Bos | D147: Belgium | E147: French Press 1L | F147: =IFERROR(INDEX(Products!$B$2:$B$9,MATCH(E147,Products!$A$2:$A$9,0)),"Unknown product") -> Coffee | G147: 2 | H147: 29.95 | I147: =IF(OR(G147="",L147="Price differs from list"),"",G147*H147) -> 59.9 | J147: PayPal | K147: =DATE(YEAR(B147),MONTH(B147),1) -> 46204 | L147: =IF(G147="","Missing qty",IF(D147="","Missing country",IF(ABS(H147-INDEX(Products!$C$2:$C$9,MATCH(E147,Products!$A$2:$A$9,0)))>0.005,"Price differs from list","")))
A148: LK-2048 | B148: 46219 | C148: Sophie Müller | D148: Belgium | E148: French Press 1L | F148: =IFERROR(INDEX(Products!$B$2:$B$9,MATCH(E148,Products!$A$2:$A$9,0)),"Unknown product") -> Coffee | G148: 2 | H148: 29.95 | I148: =IF(OR(G148="",L148="Price differs from list"),"",G148*H148) -> 59.9 | J148: Card | K148: =DATE(YEAR(B148),MONTH(B148),1) -> 46204 | L148: =IF(G148="","Missing qty",IF(D148="","Missing country",IF(ABS(H148-INDEX(Products!$C$2:$C$9,MATCH(E148,Products!$A$2:$A$9,0)))>0.005,"Price differs from list","")))
A149: LK-2050 | B149: 46220 | C149: Marie Smit | D149: Germany | E149: French Press 1L | F149: =IFERROR(INDEX(Products!$B$2:$B$9,MATCH(E149,Products!$A$2:$A$9,0)),"Unknown product") -> Coffee | G149: 2 | H149: 29.95 | I149: =IF(OR(G149="",L149="Price differs from list"),"",G149*H149) -> 59.9 | J149: Card | K149: =DATE(YEAR(B149),MONTH(B149),1) -> 46204 | L149: =IF(G149="","Missing qty",IF(D149="","Missing country",IF(ABS(H149-INDEX(Products!$C$2:$C$9,MATCH(E149,Products!$A$2:$A$9,0)))>0.005,"Price differs from list","")))
...

Sheet Products
A1: Product | B1: Category | C1: List Price | E1: Blue = input. The Clean Data tab looks up category and list price here.
A2: French Press 1L | B2: Coffee | C2: 29.95
A3: Ceramic Mug Set (4) | B3: Tableware | C3: 24.95
A4: Pour-Over Kettle | B4: Coffee | C4: 49
A5: Coffee Grinder | B5: Coffee | C5: 39.95
A6: Glass Teapot | B6: Tea | C6: 27.5
A7: Cast Iron Pan 26cm | B7: Cookware | C7: 44.95
A8: Linen Tea Towels (2) | B8: Textiles | C8: 12.95
A9: Oak Cutting Board | B9: Cookware | C9: 34

Sheet Cleaning Log
A1: Cleaning log
A4: Problem found | B4: What I did | C4: Rows
A5: Empty rows in the export | B5: Removed | C5: 4
A6: Duplicate orders (exact copies and copies with different spacing/case) | B6: Kept the first, removed the rest | C6: 18
A7: Order IDs with extra spaces | B7: Trimmed | C7: 24
A8: Dates stored as text in 5 different formats | B8: Converted to real dates (read as day/month/year, European shop) | C8: 193
A9: Customer names in caps, lowercase or with extra spaces | B9: Fixed capitalization and spacing ("de", "van" kept lowercase) | C9: 109
A10: Countries written 17 different ways (NL, Holland, Deutschland...) | B10: Standardized to 4 country names | C10: 240
A11: Product names written 28 different ways | B11: Matched to the 8 products on the price list | C11: 201
A12: Quantities stored as text ("2 pcs", " 3") | B12: Converted to numbers | C12: 55
A13: Prices stored as text (€24,95 / EUR 24.95 / 24,95 €) | B13: Converted to numbers | C13: 173
A14: Payment methods written different ways | B14: Standardized to Card, PayPal, iDEAL | C14: 231
A15: Missing quantity | B15: Kept and flagged red, needs checking with the shop | C15: 3
A16: Missing country | B16: Kept and flagged red | C16: 4
A17: Price far from the price list (decimal point missing) | B17: Kept as entered, flagged red and left out of revenue until checked | C17: 3
A19: Added so it stays clean:
A20: • Dropdowns for Country, Product and Payment, and a whole-number rule for Qty
A21: • Category and Total calculated by formula, never typed
A22: • Check column flags missing or suspicious values, flagged rows turn red
A23: • Summary tab updates automatically when data changes

Sheet Original Data
A1: order id | B1: Date | C1: customer name | D1: COUNTRY | E1: Product | F1: qty | G1: Price | H1: payment method | J1: Untouched copy of the original export, kept for comparison.
A2: LK-2001 | B2: 46204 | C2: Eva Dubois | D2: france | E2: french press 1l | F2: 3 | G2: 29,95 € | H2: Card
A3: LK-2002 | B3: 46204 | C3: Lena Müller | D3: netherlands | E3: Pour over kettle | F3: 1 | G3: 49 | H3: CARD
A4: LK-2003 | B4: 46204 | C4: paul dubois | D4: België | E4: Pour over kettle | F4: 1 | G4: 49 | H4: CARD
A5: LK-2004 | B5: 2026-07-02 | C5: julia jansen | D5: france | E5: Ceramic mug set x4 | F5: 1 | G5: €24,95 | H5: Credit card
A6: LK-2005 | B6: 02/07/2026 | C6: Daan Martin | D6: NL | E6: coffee grinder | F6: 4 | G6: 39.95 | H6: Card
A7: LK-2006 | B7: 02.07.2026 | C7: PAUL SMIT | D7: netherlands | E7: Oak Cutting Board | F7: 1 | G7: EUR 34.00 | H7: card
A8: LK-2007 | B8: 46205 | C8: Paul Hendriks | D8: germany | E8: Pour-Over Kettle | F8: 2 | G8: 49 | H8: CARD
A9: LK-2008 | B9: 02.07.2026 | C9: Lotte Hendriks | D9: Germany | E9: FRENCH PRESS 1L | F9: 3 | G9: €29,95 | H9: Paypal
A10: LK-2009 | B10: 46206 | C10: daan maes | D10: Deutschland | E10: Ceramic Mug Set (4) | F10: 3 | G10: 24.95 | H10: Card
A11: LK-2010 | B11: July 3, 2026 | C11: Noah Wagner | D11: France | E11: Glass Teapot | F11: 2 | G11: 27.5 | H11: CARD
A12: LK-2011 | B12: 03.07.2026 | C12: Lena Wagner | D12: France | E12: pour-over kettle | F12: 2 pcs | G12: 49.00 | H12: Credit card
A13: LK-2004 | B13: 2026-07-02 | C13: julia jansen | D13: france | E13: Ceramic mug set x4 | F13: 1 | G13: €24,95 | H13: Credit card
A14: LK-2012 | B14: 46207 | C14: max dubois | D14: NL | E14: Linen Tea Towels (2) | F14: 1 | G14: 12.95 | H14: ideal
A15: LK-2013 | B15: 46207 | C15: Marie Jansen | D15: Germany | E15: French Press 1L | F15: 2 | G15: EUR 29.95 | H15: PayPal
A16: LK-2014 | B16: 4 Jul 2026 | C16: Jonas Mulder | D16: Holland | E16: Pour over kettle | F16: 2 | G16: 49 | H16: iDEAL
A17: LK-2015 | B17: 46208 | C17: Eva Meijer | D17: belgium | E17: Ceramic mug set x4 | F17: 2 | G17: 24.95 | H17: ideal
A18: LK-2016 | B18: 46208 | C18: Paul Hendriks | D18: belgium | E18: FRENCH PRESS 1L | F18: 2 | G18: 29,95 € | H18: Paypal
A19: LK-2017 | B19: 2026-07-05 | C19: sophie peeters | D19: Nederland | E19: Coffee Grinder | F19: 3 | G19: 39.95 | H19: IDEAL
A20: LK-2016 | B20: 46208 | C20: Paul Hendriks | D20: belgium | E20: FRENCH PRESS 1L | F20: 2 | G20: 29,95 € | H20: Paypal
A21: LK-2018 | B21: 46209 | C21: Claire Peters | D21: belgium | E21: Oak Chopping Board | F21: 1 pcs | G21: 34.00 | H21: paypal
A22: LK-2019 | B22: 46209 | C22: Lotte Dubois | D22: Netherlands | E22: linen tea towels | F22: 2 | G22: €12,95 | H22: iDEAL
A23: LK-2020 | B23: 2026-07-07 | C23: Sem Meijer | D23: germany | E23: Linen Tea Towels (2) | F23: 1 | G23: 12.95 | H23: PayPal
A24: LK-2021 | B24: 2026-07-07 | C24: Emma Dubois | D24: germany | E24: Glass Tea Pot | F24: 2 | G24: 27.50 | H24: Card
A25: LK-2022 | B25: 07/07/2026 | C25: Anna Visser | D25: Netherlands | E25: Cast-Iron Pan 26cm | F25: 1 | G25: €44,95 | H25: iDEAL
A26: LK-2023 | B26: 46210 | C26: Anna Müller | D26: Holland | E26: Cast Iron Pan 26cm | F26: 1 | G26: 44.95 | H26: paypal
A27: LK-2024 | B27: 46210 | C27: Daan Maes | D27: Nederland | E27: French Press 1 L | F27: 1 | G27: €29,95 | H27: PayPal
A28: LK-2025 | B28: 2026-07-07 | C28: Sophie Hendriks | D28: germany | E28: pour-over kettle | F28: 2 | G28: EUR 49.00 | H28: CARD
A29: LK-2026 | B29: 08/07/2026 | C29: Eva Hendriks | D29: germany | E29: Cast Iron Pan 26cm | F29: 1 | G29: 44.95 | H29: Paypal
A30: LK-2027 | B30: 2026-07-08 | C30: emma bakker | D30: Belgium | E30: Linen Tea Towels (2) | F30: 1 | G30: 12.95 | H30: Credit card
A31: LK-2028 | B31: 2026-07-08 | C31: Finn Bos | D31: BE | E31: french press 1l | F31: 2 | G31: 29.95 | H31: paypal
A32: LK-2029 | B32: July 8, 2026 | C32: Mila Smit | D32: Germany | E32: Oak Cutting Board | F32: 1 | G32: EUR 34.00 | H32: paypal
A33: LK-2030 | B33: 46212 | C33: Sem Visser | D33: Holland | E33: glass teapot | F33: 1 | G33: 27.5 | H33: card
A34: LK-2031 | B34: 09/07/2026 | C34: Jonas Bakker | D34: Holland | E34: linen tea towels | F34: 2 | G34: 12.95 | H34: ideal
A35: LK-2024 | B35: 46210 | C35: Daan Maes | D35: Nederland | E35: French Press 1 L | F35: 1 | G35: €29,95 | H35: PayPal
A36: LK-2032 | B36: 09.07.2026 | C36: julia martin | D36: Germany | E36: FRENCH PRESS 1L | F36: 1 | G36: EUR 29.95 | H36: ideal
A37: LK-2033 | B37: 46213 | C37: Hugo Dubois | D37: Nederland | E37: Ceramic Mug Set (4) | F37: 1 | G37: 24.95 | H37: Paypal
A38: LK-2034 | B38: 11.07.2026 | C38: Sem Vos | D38: Nederland | E38: French Press 1L | F38: 1 | G38: €29,95 | H38: Credit card
A39: LK-2035 | B39: 2026-07-11 | C39: Lena Meijer | D39: Nederland | E39: FRENCH PRESS 1L | F39: 1 | G39: 29.95 | H39: Paypal
A40: LK-2036 | B40: 2026-07-11 | C40: Eva Vos | D40: NL | E40: French Press 1 L | F40: 1 pcs | G40: €29,95 | H40: Credit card
...
